Workbook

Sheet Popu_data
A1: hhid | B1: Sampling sl.no. | C1: soc_grp | D1: hhsz | E1: mhuce | F1: AE_clo&fw | G1: edu_lvl
A2: 24698_3_01 | B2: 1 | C2: 9 | D2: 1 | E2: 6721 | F2: 20000 | G2: 12
A3: 23546_4_01 | B3: 2 | C3: 3 | D3: 1 | E3: 13889 | F3: 17800 | G3: 07
A4: 20242_2_01 | B4: 3 | C4: 9 | D4: 4 | E4: 17292 | F4: 25000 | G4: 12
A5: 11812_2_02 | B5: 4 | C5: 3 | D5: 4 | E5: 7483 | F5: 5000 | G5: 08
A6: 22602_2_01 | B6: 5 | C6: 9 | D6: 2 | E6: 38792 | F6: 15000 | G6: 12
A7: 11443_2_02 | B7: 6 | C7: 1 | D7: 4 | E7: 7171 | F7: 8600 | G7: 10
A8: 11811_2_04 | B8: 7 | C8: 9 | D8: 5 | E8: 11550 | F8: 15000 | G8: 08
A9: 12279_2_01 | B9: 8 | C9: 3 | D9: 4 | E9: 17933 | F9: 13600 | G9: 08
A10: 10558_3_01 | B10: 9 | C10: 3 | D10: 1 | E10: 2467 | F10: 2000 | G10: 05
A11: 23140_4_02 | B11: 10 | C11: 1 | D11: 3 | E11: 6338 | F11: 6500 | G11: 01
A12: 10938_2_02 | B12: 11 | C12: 3 | D12: 4 | E12: 13900 | F12: 11000 | G12: 12
A13: 16062_2_02 | B13: 12 | C13: 3 | D13: 4 | E13: 11225 | F13: 6500 | G13: 08
... A247: 20657_2_02 | B247: 246 | C247: 9 | D247: 2 | E247: 11885 | F247: 12000 | G247: 10
A248: 14627_3_01 | B248: 247 | C248: 1 | D248: 5 | E248: 6767 | F248: 8000 | G248: 07 | I248: =35/253 -> 0.13833992
A249: 23144_2_01 | B249: 248 | C249: 2 | D249: 4 | E249: 12850 | F249: 3000 | G249: 12
A250: 12768_3_01 | B250: 249 | C250: 2 | D250: 6 | E250: 14175 | F250: 10000 | G250: 07
A251: 20880_4_02 | B251: 250 | C251: 3 | D251: 2 | E251: 6317 | F251: 1800 | G251: 05
A252: 21684_4_02 | B252: 251 | C252: 9 | D252: 3 | E252: 9074 | F252: 12605 | G252: 05
A253: 14057_1_01 | B253: 252 | C253: 9 | D253: 6 | E253: 16242 | F253: 12600 | G253: 12
A254: 15990_2_01 | B254: 253 | C254: 3 | D254: 4 | E254: 8633 | F254: 8750 | G254: 08

Sheet About the data
B2: Data descriotion
B3: This dataset consists of data on
B4: 1. | C4: social group (soc_grp) [code: scheduled tribe-1, scheduled caste-2, other backward class-3, others-9]
B5: 2. | C5: housheold size (hhsz)
B6: 3. | C6: monthly household usual consumption expenditure (mhuce)
B7: 4. | C7: Annual Exp on clothing, footwear etc. (AE_clo&fw)
B8: 5. | C8: Education level of the head of the household (edu_lvl)
B9: of 253 households residing in a village.
B10: hhd_id is the identification code number for the households.
B11: Sampling serial number is generated for drawing a sample.
B13: Selected population parameters:
E14: households | F14: persons
C15: Total | E15: 253 | F15: 1006
C16: No. of ST households | E16: 35 | F16: 155
C17: No. of SC households | E17: 43 | F17: 166
C18: No. of OBC households | E18: 100 | F18: 411
C19: No. of other households | E19: 75 | F19: 274
C21: Average household size | E21: = | F21: =F15/E15 -> 3.9762846
C22: Average mhuce (Rs.) | E22: = | F22: 12988.929
C23: Average mpce (Rs.) | E23: = | F23: 10386.715

Sheet Exercise
B2: Exercise:
B3: Draw a sample of 16 households by
B4: (a) | C4: SRSWR
B5: (b) | C5: SRSWOR
B6: (c) | C6: Circular systematic sampling
B7: (d) | C7: Stratified sampling with social groups as the strata
B8: and estimate
B9: 1. | C9: population
B10: 2. | C10: average household size
B11: 3. | C11: average MHUCE
B12: 4. | C12: average MUPCE
B13: 5. | C13: avearge AE-clo&fw
B14: 6. | C14: proportion of ST households

Sheet SRSWR
A1: Oder of selection | B1: RANDBETWEEN() | C1: hhid | D1: Sampling sl.no. | E1: soc_grp | F1: hhsz | G1: mhuce | H1: AE_clo&fw | I1: edu_lvl
A2: 1 | B2: 218 | C2: {=INDEX(Popu_data!A$2:A$254, B2)} -> 14875_2_02 | D2: {=INDEX(Popu_data!B$2:B$254, B2)} -> 218 | E2: {=INDEX(Popu_data!C$2:C$254, B2)} -> 3 | F2: {=INDEX(Popu_data!D$2:D$254, B2)} -> 5 | G2: {=INDEX(Popu_data!E$2:E$254, B2)} -> 7792 | H2: {=INDEX(Popu_data!F$2:F$254, B2)} -> 10500 | I2: {=INDEX(Popu_data!G$2:G$254, B2)} -> 08
A3: 2 | B3: 251 | C3: {=INDEX(Popu_data!A$2:A$254, B3)} -> 21684_4_02 | D3: {=INDEX(Popu_data!B$2:B$254, B3)} -> 251 | E3: {=INDEX(Popu_data!C$2:C$254, B3)} -> 9 | F3: {=INDEX(Popu_data!D$2:D$254, B3)} -> 3 | G3: {=INDEX(Popu_data!E$2:E$254, B3)} -> 9074 | H3: {=INDEX(Popu_data!F$2:F$254, B3)} -> 12605 | I3: {=INDEX(Popu_data!G$2:G$254, B3)} -> 05
A4: 3 | B4: 168 | C4: {=INDEX(Popu_data!A$2:A$254, B4)} -> 26115_1_01 | D4: {=INDEX(Popu_data!B$2:B$254, B4)} -> 168 | E4: {=INDEX(Popu_data!C$2:C$254, B4)} -> 3 | F4: {=INDEX(Popu_data!D$2:D$254, B4)} -> 3 | G4: {=INDEX(Popu_data!E$2:E$254, B4)} -> 19577 | H4: {=INDEX(Popu_data!F$2:F$254, B4)} -> 17550 | I4: {=INDEX(Popu_data!G$2:G$254, B4)} -> 13
A5: 4 | B5: 218 | C5: {=INDEX(Popu_data!A$2:A$254, B5)} -> 14875_2_02 | D5: {=INDEX(Popu_data!B$2:B$254, B5)} -> 218 | E5: {=INDEX(Popu_data!C$2:C$254, B5)} -> 3 | F5: {=INDEX(Popu_data!D$2:D$254, B5)} -> 5 | G5: {=INDEX(Popu_data!E$2:E$254, B5)} -> 7792 | H5: {=INDEX(Popu_data!F$2:F$254, B5)} -> 10500 | I5: {=INDEX(Popu_data!G$2:G$254, B5)} -> 08
A6: 5 | B6: 243 | C6: {=INDEX(Popu_data!A$2:A$254, B6)} -> 14942_1_01 | D6: {=INDEX(Popu_data!B$2:B$254, B6)} -> 243 | E6: {=INDEX(Popu_data!C$2:C$254, B6)} -> 1 | F6: {=INDEX(Popu_data!D$2:D$254, B6)} -> 5 | G6: {=INDEX(Popu_data!E$2:E$254, B6)} -> 17583 | H6: {=INDEX(Popu_data!F$2:F$254, B6)} -> 15000 | I6: {=INDEX(Popu_data!G$2:G$254, B6)} -> 12
A7: 6 | B7: 247 | C7: {=INDEX(Popu_data!A$2:A$254, B7)} -> 14627_3_01 | D7: {=INDEX(Popu_data!B$2:B$254, B7)} -> 247 | E7: {=INDEX(Popu_data!C$2:C$254, B7)} -> 1 | F7: {=INDEX(Popu_data!D$2:D$254, B7)} -> 5 | G7: {=INDEX(Popu_data!E$2:E$254, B7)} -> 6767 | H7: {=INDEX(Popu_data!F$2:F$254, B7)} -> 8000 | I7: {=INDEX(Popu_data!G$2:G$254, B7)} -> 07
A8: 7 | B8: 18 | C8: {=INDEX(Popu_data!A$2:A$254, B8)} -> 22510_1_01 | D8: {=INDEX(Popu_data!B$2:B$254, B8)} -> 18 | E8: {=INDEX(Popu_data!C$2:C$254, B8)} -> 3 | F8: {=INDEX(Popu_data!D$2:D$254, B8)} -> 14 | G8: {=INDEX(Popu_data!E$2:E$254, B8)} -> 19985 | H8: {=INDEX(Popu_data!F$2:F$254, B8)} -> 10740 | I8: {=INDEX(Popu_data!G$2:G$254, B8)} -> 12
A9: 8 | B9: 5 | C9: {=INDEX(Popu_data!A$2:A$254, B9)} -> 22602_2_01 | D9: {=INDEX(Popu_data!B$2:B$254, B9)} -> 5 | E9: {=INDEX(Popu_data!C$2:C$254, B9)} -> 9 | F9: {=INDEX(Popu_data!D$2:D$254, B9)} -> 2 | G9: {=INDEX(Popu_data!E$2:E$254, B9)} -> 38792 | H9: {=INDEX(Popu_data!F$2:F$254, B9)} -> 15000 | I9: {=INDEX(Popu_data!G$2:G$254, B9)} -> 12
A10: 9 | B10: 114 | C10: {=INDEX(Popu_data!A$2:A$254, B10)} -> 21467_1_01 | D10: {=INDEX(Popu_data!B$2:B$254, B10)} -> 114 | E10: {=INDEX(Popu_data!C$2:C$254, B10)} -> 9 | F10: {=INDEX(Popu_data!D$2:D$254, B10)} -> 3 | G10: {=INDEX(Popu_data!E$2:E$254, B10)} -> 18942 | H10: {=INDEX(Popu_data!F$2:F$254, B10)} -> 28000 | I10: {=INDEX(Popu_data!G$2:G$254, B10)} -> 12
A11: 10 | B11: 133 | C11: {=INDEX(Popu_data!A$2:A$254, B11)} -> 23058_2_02 | D11: {=INDEX(Popu_data!B$2:B$254, B11)} -> 133 | E11: {=INDEX(Popu_data!C$2:C$254, B11)} -> 1 | F11: {=INDEX(Popu_data!D$2:D$254, B11)} -> 5 | G11: {=INDEX(Popu_data!E$2:E$254, B11)} -> 19583 | H11: {=INDEX(Popu_data!F$2:F$254, B11)} -> 23000 | I11: {=INDEX(Popu_data!G$2:G$254, B11)} -> 12
A12: 11 | B12: 56 | C12: {=INDEX(Popu_data!A$2:A$254, B12)} -> 15573_2_01 | D12: {=INDEX(Popu_data!B$2:B$254, B12)} -> 56 | E12: {=INDEX(Popu_data!C$2:C$254, B12)} -> 2 | F12: {=INDEX(Popu_data!D$2:D$254, B12)} -> 4 | G12: {=INDEX(Popu_data!E$2:E$254, B12)} -> 9783 | H12: {=INDEX(Popu_data!F$2:F$254, B12)} -> 7000 | I12: {=INDEX(Popu_data!G$2:G$254, B12)} -> 10
A13: 12 | B13: 233 | C13: {=INDEX(Popu_data!A$2:A$254, B13)} -> 15082_2_01 | D13: {=INDEX(Popu_data!B$2:B$254, B13)} -> 233 | E13: {=INDEX(Popu_data!C$2:C$254, B13)} -> 9 | F13: {=INDEX(Popu_data!D$2:D$254, B13)} -> 5 | G13: {=INDEX(Popu_data!E$2:E$254, B13)} -> 19830 | H13: {=INDEX(Popu_data!F$2:F$254, B13)} -> 15000 | I13: {=INDEX(Popu_data!G$2:G$254, B13)} -> 12
... A26: 25 | B26: 28 | C26: {=INDEX(Popu_data!A$2:A$254, B26)} -> 21507_4_01 | D26: {=INDEX(Popu_data!B$2:B$254, B26)} -> 28 | E26: {=INDEX(Popu_data!C$2:C$254, B26)} -> 2 | F26: {=INDEX(Popu_data!D$2:D$254, B26)} -> 1 | G26: {=INDEX(Popu_data!E$2:E$254, B26)} -> 3817 | H26: {=INDEX(Popu_data!F$2:F$254, B26)} -> 2000 | I26: {=INDEX(Popu_data!G$2:G$254, B26)} -> 07
D28: N = | E28: 253
D29: n = | E29: 25
D30: Estimates under SRSWR
D31: population | E31: Avg. hh size | F31: Avg MHUCE | G31: Avg MUPCE | H31: Avg AE-Clo&fw | I31: proportion of ST households
D32: =SUM(F2:F26)*E28/E29 -> 1113.2 | E32: =SUM(F2:F26)/E29 -> 4.4 | F32: =SUM(G2:G26)/E29 -> 14674.48 | G32: =SUM(G2:G26) / SUM(F2:F26) -> 3335.1091 | H32: =SUM(H2:H26)/SUM(F2:F26) -> 2743.5909 | I32: =COUNTIF(E2:E26,1)/25 -> 0.16

Sheet Rand_no__SRSWOR
A1: hhid | B1: Sampling sl.no. | C1: soc_grp | D1: hhsz | E1: mhuce | F1: AE_clo&fw | G1: edu_lvl | H1: rand()
A2: 24698_3_01 | B2: 1 | C2: 9 | D2: 1 | E2: 6721 | F2: 20000 | G2: 12 | H2: 0.95572801
A3: 23546_4_01 | B3: 2 | C3: 3 | D3: 1 | E3: 13889 | F3: 17800 | G3: 07 | H3: 0.60853161
A4: 20242_2_01 | B4: 3 | C4: 9 | D4: 4 | E4: 17292 | F4: 25000 | G4: 12 | H4: 0.46409164
A5: 11812_2_02 | B5: 4 | C5: 3 | D5: 4 | E5: 7483 | F5: 5000 | G5: 08 | H5: 0.82035306
A6: 22602_2_01 | B6: 5 | C6: 9 | D6: 2 | E6: 38792 | F6: 15000 | G6: 12 | H6: 0.9858668
A7: 11443_2_02 | B7: 6 | C7: 1 | D7: 4 | E7: 7171 | F7: 8600 | G7: 10 | H7: 0.34532032
A8: 11811_2_04 | B8: 7 | C8: 9 | D8: 5 | E8: 11550 | F8: 15000 | G8: 08 | H8: 0.71779017
A9: 12279_2_01 | B9: 8 | C9: 3 | D9: 4 | E9: 17933 | F9: 13600 | G9: 08 | H9: 0.026357764
A10: 10558_3_01 | B10: 9 | C10: 3 | D10: 1 | E10: 2467 | F10: 2000 | G10: 05 | H10: 0.090376454
A11: 23140_4_02 | B11: 10 | C11: 1 | D11: 3 | E11: 6338 | F11: 6500 | G11: 01 | H11: 0.68818969
A12: 10938_2_02 | B12: 11 | C12: 3 | D12: 4 | E12: 13900 | F12: 11000 | G12: 12 | H12: 0.48024769
A13: 16062_2_02 | B13: 12 | C13: 3 | D13: 4 | E13: 11225 | F13: 6500 | G13: 08 | H13: 0.82126084
... A254: 15990_2_01 | B254: 253 | C254: 3 | D254: 4 | E254: 8633 | F254: 8750 | G254: 08 | H254: 0.65085127

Sheet SRSWOR
A1: hhid | B1: Sampling sl.no. | C1: soc_grp | D1: hhsz | E1: mhuce | F1: AE_clo&fw | G1: edu_lvl | H1: rand()
A2: 12333_2_02 | B2: 75 | C2: 1 | D2: 4 | E2: 10158 | F2: 9700 | G2: 12 | H2: 0.0098277536
A3: 15082_2_01 | B3: 233 | C3: 9 | D3: 5 | E3: 19830 | F3: 15000 | G3: 12 | H3: 0.012975017
A4: 15573_2_01 | B4: 56 | C4: 2 | D4: 4 | E4: 9783 | F4: 7000 | G4: 10 | H4: 0.025070651
A5: 12279_2_01 | B5: 8 | C5: 3 | D5: 4 | E5: 17933 | F5: 13600 | G5: 08 | H5: 0.026357764
A6: 13851_2_01 | B6: 173 | C6: 1 | D6: 9 | E6: 10900 | F6: 12000 | G6: 10 | H6: 0.033688856
A7: 23105_2_01 | B7: 72 | C7: 9 | D7: 2 | E7: 17237 | F7: 7540 | G7: 13 | H7: 0.039764197
A8: 15392_2_02 | B8: 150 | C8: 9 | D8: 3 | E8: 14083 | F8: 7500 | G8: 12 | H8: 0.044829297
A9: 13489_3_02 | B9: 186 | C9: 9 | D9: 3 | E9: 7201 | F9: 5400 | G9: 07 | H9: 0.049299301
A10: 16593_2_01 | B10: 175 | C10: 9 | D10: 4 | E10: 6167 | F10: 10000 | G10: 08 | H10: 0.062541836
A11: 13985_2_02 | B11: 238 | C11: 3 | D11: 4 | E11: 12792 | F11: 6000 | G11: 10 | H11: 0.062660498
A12: 14959_2_01 | B12: 60 | C12: 3 | D12: 3 | E12: 8025 | F12: 13500 | G12: 13 | H12: 0.066453198
A13: 10302_2_02 | B13: 89 | C13: 9 | D13: 5 | E13: 11333 | F13: 9500 | G13: 10 | H13: 0.072033083
... A26: 20084_3_02 | B26: 101 | C26: 1 | D26: 6 | E26: 31223 | F26: 27000 | G26: 10 | H26: 0.12396152
B28: N = | C28: 253
B29: n = | C29: 25
B30: Estimates under SRSWOR
B31: population | C31: Avg. hh size | D31: Avg MHUCE | E31: Avg MUPCE | F31: Avg AE-Clo&fw | G31: proportion of ST households
B32: =SUM(D2:D26)*C28/C29 -> 920.92 | C32: =SUM(D2:D26)/C29 -> 3.64 | D32: =SUM(E2:E26)/C29 -> 10607.12 | E32: =SUM(E2:E26) / SUM(D2:D26) -> 2914.044 | F32: =SUM(F2:F26)/SUM(D2:D26) -> 2435.8242 | G32: =COUNTIF(C2:C26,1)/25 -> 0.12

Sheet Lin_Sys
A1: Sample_no | B1: k_interval | C1: r_start | D1: Sel_Index | E1: hhid | F1: Sampling sl.no. | G1: soc_grp | H1: hhsz | I1: mhuce | J1: AE_clo&fw | K1: edu_lvl
A2: 1 | B2: =INT(253/25) -> 10 | C2: 8 | D2: =$C$2 + (A2 - 1) * $B$2 -> 8 | E2: {=INDEX(Popu_data!A$2:A$254, D2)} -> 12279_2_01 | F2: {=INDEX(Popu_data!B$2:B$254, D2)} -> 8 | G2: {=INDEX(Popu_data!C$2:C$254, D2)} -> 3 | H2: {=INDEX(Popu_data!D$2:D$254, D2)} -> 4 | I2: {=INDEX(Popu_data!E$2:E$254, D2)} -> 17933 | J2: {=INDEX(Popu_data!F$2:F$254, D2)} -> 13600 | K2: {=INDEX(Popu_data!G$2:G$254, D2)} -> 08
A3: 2 | B3: =INT(253/25) -> 10 | C3: 8 | D3: =$C$2 + (A3 - 1) * $B$2 -> 18 | E3: {=INDEX(Popu_data!A$2:A$254, D3)} -> 22510_1_01 | F3: {=INDEX(Popu_data!B$2:B$254, D3)} -> 18 | G3: {=INDEX(Popu_data!C$2:C$254, D3)} -> 3 | H3: {=INDEX(Popu_data!D$2:D$254, D3)} -> 14 | I3: {=INDEX(Popu_data!E$2:E$254, D3)} -> 19985 | J3: {=INDEX(Popu_data!F$2:F$254, D3)} -> 10740 | K3: {=INDEX(Popu_data!G$2:G$254, D3)} -> 12
A4: 3 | B4: =INT(253/25) -> 10 | C4: 8 | D4: =$C$2 + (A4 - 1) * $B$2 -> 28 | E4: {=INDEX(Popu_data!A$2:A$254, D4)} -> 21507_4_01 | F4: {=INDEX(Popu_data!B$2:B$254, D4)} -> 28 | G4: {=INDEX(Popu_data!C$2:C$254, D4)} -> 2 | H4: {=INDEX(Popu_data!D$2:D$254, D4)} -> 1 | I4: {=INDEX(Popu_data!E$2:E$254, D4)} -> 3817 | J4: {=INDEX(Popu_data!F$2:F$254, D4)} -> 2000 | K4: {=INDEX(Popu_data!G$2:G$254, D4)} -> 07
A5: 4 | B5: =INT(253/25) -> 10 | C5: 8 | D5: =$C$2 + (A5 - 1) * $B$2 -> 38 | E5: {=INDEX(Popu_data!A$2:A$254, D5)} -> 24519_2_01 | F5: {=INDEX(Popu_data!B$2:B$254, D5)} -> 38 | G5: {=INDEX(Popu_data!C$2:C$254, D5)} -> 3 | H5: {=INDEX(Popu_data!D$2:D$254, D5)} -> 3 | I5: {=INDEX(Popu_data!E$2:E$254, D5)} -> 23750 | J5: {=INDEX(Popu_data!F$2:F$254, D5)} -> 15000 | K5: {=INDEX(Popu_data!G$2:G$254, D5)} -> 12
A6: 5 | B6: =INT(253/25) -> 10 | C6: 8 | D6: =$C$2 + (A6 - 1) * $B$2 -> 48 | E6: {=INDEX(Popu_data!A$2:A$254, D6)} -> 15997_2_02 | F6: {=INDEX(Popu_data!B$2:B$254, D6)} -> 48 | G6: {=INDEX(Popu_data!C$2:C$254, D6)} -> 2 | H6: {=INDEX(Popu_data!D$2:D$254, D6)} -> 5 | I6: {=INDEX(Popu_data!E$2:E$254, D6)} -> 11602 | J6: {=INDEX(Popu_data!F$2:F$254, D6)} -> 7000 | K6: {=INDEX(Popu_data!G$2:G$254, D6)} -> 10
A7: 6 | B7: =INT(253/25) -> 10 | C7: 8 | D7: =$C$2 + (A7 - 1) * $B$2 -> 58 | E7: {=INDEX(Popu_data!A$2:A$254, D7)} -> 22082_4_02 | F7: {=INDEX(Popu_data!B$2:B$254, D7)} -> 58 | G7: {=INDEX(Popu_data!C$2:C$254, D7)} -> 9 | H7: {=INDEX(Popu_data!D$2:D$254, D7)} -> 4 | I7: {=INDEX(Popu_data!E$2:E$254, D7)} -> 13425 | J7: {=INDEX(Popu_data!F$2:F$254, D7)} -> 18600 | K7: {=INDEX(Popu_data!G$2:G$254, D7)} -> 13
A8: 7 | B8: =INT(253/25) -> 10 | C8: 8 | D8: =$C$2 + (A8 - 1) * $B$2 -> 68 | E8: {=INDEX(Popu_data!A$2:A$254, D8)} -> 15081_2_02 | F8: {=INDEX(Popu_data!B$2:B$254, D8)} -> 68 | G8: {=INDEX(Popu_data!C$2:C$254, D8)} -> 2 | H8: {=INDEX(Popu_data!D$2:D$254, D8)} -> 3 | I8: {=INDEX(Popu_data!E$2:E$254, D8)} -> 8680 | J8: {=INDEX(Popu_data!F$2:F$254, D8)} -> 4060 | K8: {=INDEX(Popu_data!G$2:G$254, D8)} -> 10
A9: 8 | B9: =INT(253/25) -> 10 | C9: 8 | D9: =$C$2 + (A9 - 1) * $B$2 -> 78 | E9: {=INDEX(Popu_data!A$2:A$254, D9)} -> 24001_3_02 | F9: {=INDEX(Popu_data!B$2:B$254, D9)} -> 78 | G9: {=INDEX(Popu_data!C$2:C$254, D9)} -> 1 | H9: {=INDEX(Popu_data!D$2:D$254, D9)} -> 5 | I9: {=INDEX(Popu_data!E$2:E$254, D9)} -> 16417 | J9: {=INDEX(Popu_data!F$2:F$254, D9)} -> 25000 | K9: {=INDEX(Popu_data!G$2:G$254, D9)} -> 12
A10: 9 | B10: =INT(253/25) -> 10 | C10: 8 | D10: =$C$2 + (A10 - 1) * $B$2 -> 88 | E10: {=INDEX(Popu_data!A$2:A$254, D10)} -> 25284_4_02 | F10: {=INDEX(Popu_data!B$2:B$254, D10)} -> 88 | G10: {=INDEX(Popu_data!C$2:C$254, D10)} -> 3 | H10: {=INDEX(Popu_data!D$2:D$254, D10)} -> 1 | I10: {=INDEX(Popu_data!E$2:E$254, D10)} -> 7125 | J10: {=INDEX(Popu_data!F$2:F$254, D10)} -> 1500 | K10: {=INDEX(Popu_data!G$2:G$254, D10)} -> 06
A11: 10 | B11: =INT(253/25) -> 10 | C11: 8 | D11: =$C$2 + (A11 - 1) * $B$2 -> 98 | E11: {=INDEX(Popu_data!A$2:A$254, D11)} -> 13562_1_01 | F11: {=INDEX(Popu_data!B$2:B$254, D11)} -> 98 | G11: {=INDEX(Popu_data!C$2:C$254, D11)} -> 9 | H11: {=INDEX(Popu_data!D$2:D$254, D11)} -> 3 | I11: {=INDEX(Popu_data!E$2:E$254, D11)} -> 7175 | J11: {=INDEX(Popu_data!F$2:F$254, D11)} -> 4500 | K11: {=INDEX(Popu_data!G$2:G$254, D11)} -> 08
A12: 11 | B12: =INT(253/25) -> 10 | C12: 8 | D12: =$C$2 + (A12 - 1) * $B$2 -> 108 | E12: {=INDEX(Popu_data!A$2:A$254, D12)} -> 12075_2_01 | F12: {=INDEX(Popu_data!B$2:B$254, D12)} -> 108 | G12: {=INDEX(Popu_data!C$2:C$254, D12)} -> 2 | H12: {=INDEX(Popu_data!D$2:D$254, D12)} -> 4 | I12: {=INDEX(Popu_data!E$2:E$254, D12)} -> 11679 | J12: {=INDEX(Popu_data!F$2:F$254, D12)} -> 6750 | K12: {=INDEX(Popu_data!G$2:G$254, D12)} -> 10
A13: 12 | B13: =INT(253/25) -> 10 | C13: 8 | D13: =$C$2 + (A13 - 1) * $B$2 -> 118 | E13: {=INDEX(Popu_data!A$2:A$254, D13)} -> 24471_4_01 | F13: {=INDEX(Popu_data!B$2:B$254, D13)} -> 118 | G13: {=INDEX(Popu_data!C$2:C$254, D13)} -> 9 | H13: {=INDEX(Popu_data!D$2:D$254, D13)} -> 5 | I13: {=INDEX(Popu_data!E$2:E$254, D13)} -> 16667 | J13: {=INDEX(Popu_data!F$2:F$254, D13)} -> 8500 | K13: {=INDEX(Popu_data!G$2:G$254, D13)} -> 07
... A26: 25 | B26: =INT(253/25) -> 10 | C26: 8 | D26: =$C$2 + (A26 - 1) * $B$2 -> 248 | E26: {=INDEX(Popu_data!A$2:A$254, D26)} -> 23144_2_01 | F26: {=INDEX(Popu_data!B$2:B$254, D26)} -> 248 | G26: {=INDEX(Popu_data!C$2:C$254, D26)} -> 2 | H26: {=INDEX(Popu_data!D$2:D$254, D26)} -> 4 | I26: {=INDEX(Popu_data!E$2:E$254, D26)} -> 12850 | J26: {=INDEX(Popu_data!F$2:F$254, D26)} -> 3000 | K26: {=INDEX(Popu_data!G$2:G$254, D26)} -> 12
F28: N = | G28: 253
F29: n = | G29: 25
F30: Estimates under Linear systematic
F31: population | G31: Avg. hh size | H31: Avg MHUCE | I31: Avg MUPCE | J31: Avg AE-Clo&fw | K31: proportion of ST households
F32: =SUM(H2:H26)*G28/G29 -> 1092.96 | G32: =SUM(H2:H26)/G29 -> 4.32 | H32: =SUM(I2:I26)/G29 -> 13080.2 | I32: =SUM(I2:I26) / SUM(H2:H26) -> 3027.8241 | J32: =SUM(J2:J26)/SUM(H2:H26) -> 2404.1667 | K32: =COUNTIF(G2:G26,1)/25 -> 0.08

Sheet Cir_Sys
A1: Sample_no | B1: k_interval | C1: r_start | D1: sample indices | E1: hhid | F1: Sampling sl.no. | G1: soc_grp | H1: hhsz | I1: mhuce | J1: AE_clo&fw | K1: edu_lvl
A2: 1 | B2: =INT(253/25) -> 10 | C2: 17 | D2: =MOD($C$2 + (ROW()-2)*10 - 1, 253) + 1 -> 17 | E2: {=INDEX(Popu_data!A$2:A$254, D2)} -> 23700_1_01 | F2: {=INDEX(Popu_data!B$2:B$254, D2)} -> 17 | G2: {=INDEX(Popu_data!C$2:C$254, D2)} -> 3 | H2: {=INDEX(Popu_data!D$2:D$254, D2)} -> 8 | I2: {=INDEX(Popu_data!E$2:E$254, D2)} -> 15500 | J2: {=INDEX(Popu_data!F$2:F$254, D2)} -> 18000 | K2: {=INDEX(Popu_data!G$2:G$254, D2)} -> 12
A3: 2 | B3: =INT(253/25) -> 10 | C3: 17 | D3: =MOD($C$2 + (ROW()-2)*10 - 1, 253) + 1 -> 27 | E3: {=INDEX(Popu_data!A$2:A$254, D3)} -> 12829_3_01 | F3: {=INDEX(Popu_data!B$2:B$254, D3)} -> 27 | G3: {=INDEX(Popu_data!C$2:C$254, D3)} -> 9 | H3: {=INDEX(Popu_data!D$2:D$254, D3)} -> 4 | I3: {=INDEX(Popu_data!E$2:E$254, D3)} -> 7750 | J3: {=INDEX(Popu_data!F$2:F$254, D3)} -> 15000 | K3: {=INDEX(Popu_data!G$2:G$254, D3)} -> 07
A4: 3 | B4: =INT(253/25) -> 10 | C4: 17 | D4: =MOD($C$2 + (ROW()-2)*10 - 1, 253) + 1 -> 37 | E4: {=INDEX(Popu_data!A$2:A$254, D4)} -> 12399_1_01 | F4: {=INDEX(Popu_data!B$2:B$254, D4)} -> 37 | G4: {=INDEX(Popu_data!C$2:C$254, D4)} -> 2 | H4: {=INDEX(Popu_data!D$2:D$254, D4)} -> 4 | I4: {=INDEX(Popu_data!E$2:E$254, D4)} -> 6833 | J4: {=INDEX(Popu_data!F$2:F$254, D4)} -> 4000 | K4: {=INDEX(Popu_data!G$2:G$254, D4)} -> 08
A5: 4 | B5: =INT(253/25) -> 10 | C5: 17 | D5: =MOD($C$2 + (ROW()-2)*10 - 1, 253) + 1 -> 47 | E5: {=INDEX(Popu_data!A$2:A$254, D5)} -> 24417_4_01 | F5: {=INDEX(Popu_data!B$2:B$254, D5)} -> 47 | G5: {=INDEX(Popu_data!C$2:C$254, D5)} -> 9 | H5: {=INDEX(Popu_data!D$2:D$254, D5)} -> 2 | I5: {=INDEX(Popu_data!E$2:E$254, D5)} -> 5000 | J5: {=INDEX(Popu_data!F$2:F$254, D5)} -> 5000 | K5: {=INDEX(Popu_data!G$2:G$254, D5)} -> 01
A6: 5 | B6: =INT(253/25) -> 10 | C6: 17 | D6: =MOD($C$2 + (ROW()-2)*10 - 1, 253) + 1 -> 57 | E6: {=INDEX(Popu_data!A$2:A$254, D6)} -> 20501_4_01 | F6: {=INDEX(Popu_data!B$2:B$254, D6)} -> 57 | G6: {=INDEX(Popu_data!C$2:C$254, D6)} -> 9 | H6: {=INDEX(Popu_data!D$2:D$254, D6)} -> 4 | I6: {=INDEX(Popu_data!E$2:E$254, D6)} -> 11653 | J6: {=INDEX(Popu_data!F$2:F$254, D6)} -> 10000 | K6: {=INDEX(Popu_data!G$2:G$254, D6)} -> 07
A7: 6 | B7: =INT(253/25) -> 10 | C7: 17 | D7: =MOD($C$2 + (ROW()-2)*10 - 1, 253) + 1 -> 67 | E7: {=INDEX(Popu_data!A$2:A$254, D7)} -> 12609_2_01 | F7: {=INDEX(Popu_data!B$2:B$254, D7)} -> 67 | G7: {=INDEX(Popu_data!C$2:C$254, D7)} -> 9 | H7: {=INDEX(Popu_data!D$2:D$254, D7)} -> 7 | I7: {=INDEX(Popu_data!E$2:E$254, D7)} -> 8417 | J7: {=INDEX(Popu_data!F$2:F$254, D7)} -> 12000 | K7: {=INDEX(Popu_data!G$2:G$254, D7)} -> 10
A8: 7 | B8: =INT(253/25) -> 10 | C8: 17 | D8: =MOD($C$2 + (ROW()-2)*10 - 1, 253) + 1 -> 77 | E8: {=INDEX(Popu_data!A$2:A$254, D8)} -> 11311_2_01 | F8: {=INDEX(Popu_data!B$2:B$254, D8)} -> 77 | G8: {=INDEX(Popu_data!C$2:C$254, D8)} -> 3 | H8: {=INDEX(Popu_data!D$2:D$254, D8)} -> 4 | I8: {=INDEX(Popu_data!E$2:E$254, D8)} -> 7055 | J8: {=INDEX(Popu_data!F$2:F$254, D8)} -> 7589 | K8: {=INDEX(Popu_data!G$2:G$254, D8)} -> 11
A9: 8 | B9: =INT(253/25) -> 10 | C9: 17 | D9: =MOD($C$2 + (ROW()-2)*10 - 1, 253) + 1 -> 87 | E9: {=INDEX(Popu_data!A$2:A$254, D9)} -> 17415_1_01 | F9: {=INDEX(Popu_data!B$2:B$254, D9)} -> 87 | G9: {=INDEX(Popu_data!C$2:C$254, D9)} -> 1 | H9: {=INDEX(Popu_data!D$2:D$254, D9)} -> 4 | I9: {=INDEX(Popu_data!E$2:E$254, D9)} -> 17055 | J9: {=INDEX(Popu_data!F$2:F$254, D9)} -> 20000 | K9: {=INDEX(Popu_data!G$2:G$254, D9)} -> 12
A10: 9 | B10: =INT(253/25) -> 10 | C10: 17 | D10: =MOD($C$2 + (ROW()-2)*10 - 1, 253) + 1 -> 97 | E10: {=INDEX(Popu_data!A$2:A$254, D10)} -> 20728_4_02 | F10: {=INDEX(Popu_data!B$2:B$254, D10)} -> 97 | G10: {=INDEX(Popu_data!C$2:C$254, D10)} -> 3 | H10: {=INDEX(Popu_data!D$2:D$254, D10)} -> 1 | I10: {=INDEX(Popu_data!E$2:E$254, D10)} -> 33750 | J10: {=INDEX(Popu_data!F$2:F$254, D10)} -> 19800 | K10: {=INDEX(Popu_data!G$2:G$254, D10)} -> 12
A11: 10 | B11: =INT(253/25) -> 10 | C11: 17 | D11: =MOD($C$2 + (ROW()-2)*10 - 1, 253) + 1 -> 107 | E11: {=INDEX(Popu_data!A$2:A$254, D11)} -> 21188_4_02 | F11: {=INDEX(Popu_data!B$2:B$254, D11)} -> 107 | G11: {=INDEX(Popu_data!C$2:C$254, D11)} -> 3 | H11: {=INDEX(Popu_data!D$2:D$254, D11)} -> 8 | I11: {=INDEX(Popu_data!E$2:E$254, D11)} -> 19775 | J11: {=INDEX(Popu_data!F$2:F$254, D11)} -> 7680 | K11: {=INDEX(Popu_data!G$2:G$254, D11)} -> 07
A12: 11 | B12: =INT(253/25) -> 10 | C12: 17 | D12: =MOD($C$2 + (ROW()-2)*10 - 1, 253) + 1 -> 117 | E12: {=INDEX(Popu_data!A$2:A$254, D12)} -> 11078_3_01 | F12: {=INDEX(Popu_data!B$2:B$254, D12)} -> 117 | G12: {=INDEX(Popu_data!C$2:C$254, D12)} -> 2 | H12: {=INDEX(Popu_data!D$2:D$254, D12)} -> 4 | I12: {=INDEX(Popu_data!E$2:E$254, D12)} -> 12415 | J12: {=INDEX(Popu_data!F$2:F$254, D12)} -> 22000 | K12: {=INDEX(Popu_data!G$2:G$254, D12)} -> 07
A13: 12 | B13: =INT(253/25) -> 10 | C13: 17 | D13: =MOD($C$2 + (ROW()-2)*10 - 1, 253) + 1 -> 127 | E13: {=INDEX(Popu_data!A$2:A$254, D13)} -> 13075_2_01 | F13: {=INDEX(Popu_data!B$2:B$254, D13)} -> 127 | G13: {=INDEX(Popu_data!C$2:C$254, D13)} -> 3 | H13: {=INDEX(Popu_data!D$2:D$254, D13)} -> 6 | I13: {=INDEX(Popu_data!E$2:E$254, D13)} -> 7925 | J13: {=INDEX(Popu_data!F$2:F$254, D13)} -> 6500 | K13: {=INDEX(Popu_data!G$2:G$254, D13)} -> 10
... A26: 25 | B26: =INT(253/25) -> 10 | C26: 17 | D26: =MOD($C$2 + (ROW()-2)*10 - 1, 253) + 1 -> 4 | E26: {=INDEX(Popu_data!A$2:A$254, D26)} -> 11812_2_02 | F26: {=INDEX(Popu_data!B$2:B$254, D26)} -> 4 | G26: {=INDEX(Popu_data!C$2:C$254, D26)} -> 3 | H26: {=INDEX(Popu_data!D$2:D$254, D26)} -> 4 | I26: {=INDEX(Popu_data!E$2:E$254, D26)} -> 7483 | J26: {=INDEX(Popu_data!F$2:F$254, D26)} -> 5000 | K26: {=INDEX(Popu_data!G$2:G$254, D26)} -> 08
F28: N = | G28: 253
F29: n = | G29: 25
F30: Estimates under Circuler systematic
F31: population | G31: Avg. hh size | H31: Avg MHUCE | I31: Avg MUPCE | J31: Avg AE-Clo&fw | K31: proportion of ST households
F32: =SUM(H2:H26)*G28/G29 -> 1062.6 | G32: =SUM(H2:H26)/G29 -> 4.2 | H32: =SUM(I2:I26)/G29 -> 12536.16 | I32: =SUM(I2:I26) / SUM(H2:H26) -> 2984.8 | J32: =SUM(J2:J26)/SUM(H2:H26) -> 2841.6095 | K32: =COUNTIF(G2:G26,1)/25 -> 0.16

Sheet Stratum_info
A1: hhid | B1: Sample_Srl_no | C1: Social_group | D1: HH_Size | E1: Usual_Con_Exp_Month | F1: Annual Exp on clothing, footwear etc.(Rs.) | G1: edu_level | H1: Nh​​ | I1: nh​ | J1: rand()
A2: 16593_2_01 | B2: 175 | C2: 9 | D2: 4 | E2: 6167 | F2: 10000 | G2: 08 | H2: =COUNTIF(Popu_data!C:C, C2) -> 75 | I2: =H2/253*25 -> 7.4110672 | J2: 0.019549967
A3: 21188_4_02 | B3: 107 | C3: 3 | D3: 8 | E3: 19775 | F3: 7680 | G3: 07 | H3: =COUNTIF(Popu_data!C:C, C3) -> 100 | I3: =H3/253*25 -> 9.8814229 | J3: 0.0046685745
A4: 21325_2_01 | B4: 237 | C4: 9 | D4: 4 | E4: 35667 | F4: 25000 | G4: 12 | H4: =COUNTIF(Popu_data!C:C, C4) -> 75 | I4: =H4/253*25 -> 7.4110672 | J4: 0.032043415
A5: 13856_1_01 | B5: 102 | C5: 3 | D5: 5 | E5: 16150 | F5: 7000 | G5: 12 | H5: =COUNTIF(Popu_data!C:C, C5) -> 100 | I5: =H5/253*25 -> 9.8814229 | J5: 0.010703972
A6: 17162_2_02 | B6: 39 | C6: 9 | D6: 1 | E6: 6833 | F6: 3000 | G6: 10 | H6: =COUNTIF(Popu_data!C:C, C6) -> 75 | I6: =H6/253*25 -> 7.4110672 | J6: 0.046206864
A7: 13323_3_01 | B7: 80 | C7: 1 | D7: 5 | E7: 9283 | F7: 6500 | G7: 07 | H7: =COUNTIF(Popu_data!C:C, C7) -> 35 | I7: 4 | J7: 0.07965552
A8: 22690_4_01 | B8: 242 | C8: 9 | D8: 2 | E8: 12608 | F8: 5200 | G8: 12 | H8: =COUNTIF(Popu_data!C:C, C8) -> 75 | I8: =H8/253*25 -> 7.4110672 | J8: 0.074306197
A9: 10938_2_02 | B9: 11 | C9: 3 | D9: 4 | E9: 13900 | F9: 11000 | G9: 12 | H9: =COUNTIF(Popu_data!C:C, C9) -> 100 | I9: =H9/253*25 -> 9.8814229 | J9: 0.012416982
A10: 13259_2_01 | B10: 190 | C10: 3 | D10: 3 | E10: 5436 | F10: 4730 | G10: 12 | H10: =COUNTIF(Popu_data!C:C, C10) -> 100 | I10: =H10/253*25 -> 9.8814229 | J10: 0.025380164
A11: 14932_1_01 | B11: 94 | C11: 1 | D11: 4 | E11: 10217 | F11: 13500 | G11: 13 | H11: =COUNTIF(Popu_data!C:C, C11) -> 35 | I11: 4 | J11: 0.12349742
A12: 25284_4_02 | B12: 88 | C12: 3 | D12: 1 | E12: 7125 | F12: 1500 | G12: 06 | H12: =COUNTIF(Popu_data!C:C, C12) -> 100 | I12: =H12/253*25 -> 9.8814229 | J12: 0.025970926
A13: 23546_4_01 | B13: 2 | C13: 3 | D13: 1 | E13: 13889 | F13: 17800 | G13: 07 | H13: =COUNTIF(Popu_data!C:C, C13) -> 100 | I13: =H13/253*25 -> 9.8814229 | J13: 0.027386031
A14: 21507_4_01 | B14: 28 | C14: 2 | D14: 1 | E14: 3817 | F14: 2000 | G14: 07 | H14: =COUNTIF(Popu_data!C:C, C14) -> 43 | I14: =H14/253*25 -> 4.2490119 | J14: 0.019095169
A15: 11845_2_01 | B15: 23 | C15: 3 | D15: 3 | E15: 15908 | F15: 8500 | G15: 11 | H15: =COUNTIF(Popu_data!C:C, C15) -> 100 | I15: =H15/253*25 -> 9.8814229 | J15: 0.027835042
A16: 12316_3_01 | B16: 45 | C16: 3 | D16: 4 | E16: 13042 | F16: 7500 | G16: 07 | H16: =COUNTIF(Popu_data!C:C, C16) -> 100 | I16: =H16/253*25 -> 9.8814229 | J16: 0.037487648
A17: 20580_3_01 | B17: 54 | C17: 3 | D17: 3 | E17: 51300 | F17: 15000 | G17: 13 | H17: =COUNTIF(Popu_data!C:C, C17) -> 100 | I17: =H17/253*25 -> 9.8814229 | J17: 0.045448336
A18: 24888_4_06 | B18: 179 | C18: 3 | D18: 1 | E18: 20467 | F18: 2000 | G18: 06 | H18: =COUNTIF(Popu_data!C:C, C18) -> 100 | I18: =H18/253*25 -> 9.8814229 | J18: 0.049639455
A19: 14533_3_01 | B19: 14 | C19: 3 | D19: 6 | E19: 15317 | F19: 10000 | G19: 07 | H19: =COUNTIF(Popu_data!C:C, C19) -> 100 | I19: =H19/253*25 -> 9.8814229 | J19: 0.059499704
A20: 15143_2_03 | B20: 132 | C20: 3 | D20: 2 | E20: 8692 | F20: 5100 | G20: 12 | H20: =COUNTIF(Popu_data!C:C, C20) -> 100 | I20: =H20/253*25 -> 9.8814229 | J20: 0.064419153
A21: 20880_4_02 | B21: 250 | C21: 3 | D21: 2 | E21: 6317 | F21: 1800 | G21: 05 | H21: =COUNTIF(Popu_data!C:C, C21) -> 100 | I21: =H21/253*25 -> 9.8814229 | J21: 0.064442021
A22: 22702_3_01 | B22: 235 | C22: 3 | D22: 4 | E22: 10058 | F22: 7250 | G22: 08 | H22: =COUNTIF(Popu_data!C:C, C22) -> 100 | I22: =H22/253*25 -> 9.8814229 | J22: 0.06576161
A23: 12829_3_01 | B23: 27 | C23: 9 | D23: 4 | E23: 7750 | F23: 15000 | G23: 07 | H23: =COUNTIF(Popu_data!C:C, C23) -> 75 | I23: =H23/253*25 -> 7.4110672 | J23: 0.10396598
A24: 22255_2_01 | B24: 232 | C24: 3 | D24: 4 | E24: 11083 | F24: 7000 | G24: 11 | H24: =COUNTIF(Popu_data!C:C, C24) -> 100 | I24: =H24/253*25 -> 9.8814229 | J24: 0.07609122
A25: 23765_4_01 | B25: 206 | C25: 3 | D25: 1 | E25: 3625 | F25: 1500 | G25: 06 | H25: =COUNTIF(Popu_data!C:C, C25) -> 100 | I25: =H25/253*25 -> 9.8814229 | J25: 0.088214424
A26: 11695_1_02 | B26: 158 | C26: 3 | D26: 4 | E26: 8625 | F26: 7500 | G26: 10 | H26: =COUNTIF(Popu_data!C:C, C26) -> 100 | I26: =H26/253*25 -> 9.8814229 | J26: 0.091240945
A27: 17111_2_01 | B27: 122 | C27: 2 | D27: 4 | E27: 7491 | F27: 8500 | G27: 08 | H27: =COUNTIF(Popu_data!C:C, C27) -> 43 | I27: =H27/253*25 -> 4.2490119 | J27: 0.026366153
A28: 12609_2_01 | B28: 67 | C28: 9 | D28: 7 | E28: 8417 | F28: 12000 | G28: 10 | H28: =COUNTIF(Popu_data!C:C, C28) -> 75 | I28: =H28/253*25 -> 7.4110672 | J28: 0.12310304
A29: 16741_2_02 | B29: 55 | C29: 2 | D29: 5 | E29: 12542 | F29: 11000 | G29: 10 | H29: =COUNTIF(Popu_data!C:C, C29) -> 43 | I29: =H29/253*25 -> 4.2490119 | J29: 0.035672053
A30: 21284_1_02 | B30: 84 | C30: 9 | D30: 7 | E30: 18500 | F30: 12000 | G30: 08 | H30: =COUNTIF(Popu_data!C:C, C30) -> 75 | I30: =H30/253*25 -> 7.4110672 | J30: 0.12575303
A31: 14959_2_01 | B31: 60 | C31: 3 | D31: 3 | E31: 8025 | F31: 13500 | G31: 13 | H31: =COUNTIF(Popu_data!C:C, C31) -> 100 | I31: =H31/253*25 -> 9.8814229 | J31: 0.095666229
A32: 15088_2_02 | B32: 161 | C32: 3 | D32: 7 | E32: 34840 | F32: 11230 | G32: 12 | H32: =COUNTIF(Popu_data!C:C, C32) -> 100 | I32: =H32/253*25 -> 9.8814229 | J32: 0.10876251
A33: 12776_2_01 | B33: 63 | C33: 3 | D33: 2 | E33: 8360 | F33: 5500 | G33: 10 | H33: =COUNTIF(Popu_data!C:C, C33) -> 100 | I33: =H33/253*25 -> 9.8814229 | J33: 0.1152025
A34: 24471_4_01 | B34: 118 | C34: 9 | D34: 5 | E34: 16667 | F34: 8500 | G34: 07 | H34: =COUNTIF(Popu_data!C:C, C34) -> 75 | I34: =H34/253*25 -> 7.4110672 | J34: 0.1359585
A35: 21327_2_01 | B35: 154 | C35: 9 | D35: 3 | E35: 18383 | F35: 17000 | G35: 13 | H35: =COUNTIF(Popu_data!C:C, C35) -> 75 | I35: =H35/253*25 -> 7.4110672 | J35: 0.15471306
A36: 12279_2_01 | B36: 8 | C36: 3 | D36: 4 | E36: 17933 | F36: 13600 | G36: 08 | H36: =COUNTIF(Popu_data!C:C, C36) -> 100 | I36: =H36/253*25 -> 9.8814229 | J36: 0.12585124
... A42: 11443_1_01 | B42: 222 | C42: 3 | D42: 10 | E42: 13038 | F42: 26500 | G42: 12 | H42: =COUNTIF(Popu_data!C:C, C42) -> 100 | I42: =H42/253*25 -> 9.8814229 | J42: 0.15771641
A43: 13169_1_01 | B43: 42 | C43: 1 | D43: 5 | E43: 19917 | F43: 10000 | G43: 12 | H43: =COUNTIF(Popu_data!C:C, C43) -> 35 | I43: 4 | J43: 0.1271511
A44: 10711_2_01 | B44: 228 | C44: 3 | D44: 5 | E44: 19558 | F44: 8500 | G44: 12 | H44: =COUNTIF(Popu_data!C:C, C44) -> 100 | I44: =H44/253*25 -> 9.8814229 | J44: 0.16017453
A45: 24976_4_02 | B45: 205 | C45: 3 | D45: 4 | E45: 12158 | F45: 6600 | G45: 07 | H45: =COUNTIF(Popu_data!C:C, C45) -> 100 | I45: =H45/253*25 -> 9.8814229 | J45: 0.17894475
...

Sheet Exp_Stratified
A1: hhid | B1: Sampling sl.no. | C1: soc_grp | D1: hhsz | E1: mhuce | F1: AE_clo&fw | G1: edu_lvl | H1: Nh​​ | I1: nh​ | J1: rand()
A2: 13323_3_01 | B2: 80 | C2: 1 | D2: 5 | E2: 9283 | F2: 6500 | G2: 07 | H2: 35 | I2: 4 | J2: 0.07965552
A3: 14932_1_01 | B3: 94 | C3: 1 | D3: 4 | E3: 10217 | F3: 13500 | G3: 13 | H3: 35 | I3: 4 | J3: 0.12349742
A4: 13169_1_01 | B4: 42 | C4: 1 | D4: 5 | E4: 19917 | F4: 10000 | G4: 12 | H4: 35 | I4: 4 | J4: 0.1271511
A5: 20084_3_02 | B5: 101 | C5: 1 | D5: 6 | E5: 31223 | F5: 27000 | G5: 10 | H5: 35 | I5: 4 | J5: 0.14162989
A6: 21507_4_01 | B6: 28 | C6: 2 | D6: 1 | E6: 3817 | F6: 2000 | G6: 07 | H6: 43 | I6: 4.2490119 | J6: 0.019095169 | Q6: =COUNTIF(C2:C26,2) -> 4
A7: 17111_2_01 | B7: 122 | C7: 2 | D7: 4 | E7: 7491 | F7: 8500 | G7: 08 | H7: 43 | I7: 4.2490119 | J7: 0.026366153
A8: 16741_2_02 | B8: 55 | C8: 2 | D8: 5 | E8: 12542 | F8: 11000 | G8: 10 | H8: 43 | I8: 4.2490119 | J8: 0.035672053
A9: 10866_3_01 | B9: 156 | C9: 2 | D9: 2 | E9: 6583 | F9: 5000 | G9: 06 | H9: 43 | I9: 4.2490119 | J9: 0.10006867
A10: 21188_4_02 | B10: 107 | C10: 3 | D10: 8 | E10: 19775 | F10: 7680 | G10: 07 | H10: 100 | I10: 9.8814229 | J10: 0.0046685745
A11: 13856_1_01 | B11: 102 | C11: 3 | D11: 5 | E11: 16150 | F11: 7000 | G11: 12 | H11: 100 | I11: 9.8814229 | J11: 0.010703972
A12: 10938_2_02 | B12: 11 | C12: 3 | D12: 4 | E12: 13900 | F12: 11000 | G12: 12 | H12: 100 | I12: 9.8814229 | J12: 0.012416982
A13: 13259_2_01 | B13: 190 | C13: 3 | D13: 3 | E13: 5436 | F13: 4730 | G13: 12 | H13: 100 | I13: 9.8814229 | J13: 0.025380164
A14: 25284_4_02 | B14: 88 | C14: 3 | D14: 1 | E14: 7125 | F14: 1500 | G14: 06 | H14: 100 | I14: 9.8814229 | J14: 0.025970926
A15: 23546_4_01 | B15: 2 | C15: 3 | D15: 1 | E15: 13889 | F15: 17800 | G15: 07 | H15: 100 | I15: 9.8814229 | J15: 0.027386031
A16: 11845_2_01 | B16: 23 | C16: 3 | D16: 3 | E16: 15908 | F16: 8500 | G16: 11 | H16: 100 | I16: 9.8814229 | J16: 0.027835042
A17: 12316_3_01 | B17: 45 | C17: 3 | D17: 4 | E17: 13042 | F17: 7500 | G17: 07 | H17: 100 | I17: 9.8814229 | J17: 0.037487648
A18: 20580_3_01 | B18: 54 | C18: 3 | D18: 3 | E18: 51300 | F18: 15000 | G18: 13 | H18: 100 | I18: 9.8814229 | J18: 0.045448336
... A26: 21284_1_02 | B26: 84 | C26: 9 | D26: 7 | E26: 18500 | F26: 12000 | G26: 08 | H26: 75 | I26: 7.4110672 | J26: 0.12575303
B28: N = | C28: 253
B29: n = | C29: 25
B30: Estimates under Implicit Stratification
B31: Stratum (soc_grp) | C31: nh | D31: Nh | E31: population | F31: Avg. hh size | G31: Avg MHUCE | H31: Avg MUPCE | I31: Avg AE-Clo&fw | J31: proportion of ST ,SC, OBC, Others households
B32: 1 | C32: 4 | D32: 35 | E32: =SUMIF(C$2:C$26,B32,D$2:D$26)*D32/C32 -> 175 | F32: =SUMIF(C$2:C$26,B32,D$2:D$26)/C32 -> 5 | G32: =SUMIF(C$2:C$26,B32,E$2:E$26)/C32 -> 17660 | H32: =SUMIF(C$2:C$26,B32,E$2:E$26)/SUMIF(C$2:C$26,B32,D$2:D$26) -> 3532 | I32: =SUMIF(C$2:C$26,B32,F$2:F$26)/SUMIF(C$2:C$26,B32,D$2:D$26) -> 2850 | J32: =COUNTIF(C$2:C$26,B32)/C$29 -> 0.16
B33: 2 | C33: 4 | D33: 43 | E33: =SUMIF(C$2:C$26,B33,D$2:D$26)*D33/C33 -> 129 | F33: =SUMIF(C$2:C$26,B33,D$2:D$26)/C33 -> 3 | G33: =SUMIF(C$2:C$26,B33,E$2:E$26)/C33 -> 7608.25 | H33: =SUMIF(C$2:C$26,B33,E$2:E$26)/SUMIF(C$2:C$26,B33,D$2:D$26) -> 2536.0833 | I33: =SUMIF(C$2:C$26,B33,F$2:F$26)/SUMIF(C$2:C$26,B33,D$2:D$26) -> 2208.3333 | J33: =COUNTIF(C$2:C$26,B33)/C$29 -> 0.16
B34: 3 | C34: 10 | D34: 100 | E34: =SUMIF(C$2:C$26,B34,D$2:D$26)*D34/C34 -> 330 | F34: =SUMIF(C$2:C$26,B34,D$2:D$26)/C34 -> 3.3 | G34: =SUMIF(C$2:C$26,B34,E$2:E$26)/C34 -> 17699.2 | H34: =SUMIF(C$2:C$26,B34,E$2:E$26)/SUMIF(C$2:C$26,B34,D$2:D$26) -> 5363.3939 | I34: =SUMIF(C$2:C$26,B34,F$2:F$26)/SUMIF(C$2:C$26,B34,D$2:D$26) -> 2506.3636 | J34: =COUNTIF(C$2:C$26,B34)/C$29 -> 0.4
B35: 9 | C35: 7 | D35: 75 | E35: =SUMIF(C$2:C$26,B35,D$2:D$26)*D35/C35 -> 310.71429 | F35: =SUMIF(C$2:C$26,B35,D$2:D$26)/C35 -> 4.1428571 | G35: =SUMIF(C$2:C$26,B35,E$2:E$26)/C35 -> 13706 | H35: =SUMIF(C$2:C$26,B35,E$2:E$26)/SUMIF(C$2:C$26,B35,D$2:D$26) -> 3308.3448 | I35: =SUMIF(C$2:C$26,B35,F$2:F$26)/SUMIF(C$2:C$26,B35,D$2:D$26) -> 2834.4828 | J35: =COUNTIF(C$2:C$26,B35)/C$29 -> 0.28
B36: Total | C36: =SUM(C32:C35) -> 25 | D36: =SUM(D32:D35) -> 253 | E36: =SUM(E32:E35) -> 944.71429 | F36: =SUM(F32:F35) -> 15.442857 | G36: =SUM(G32:G35) -> 56673.45 | H36: =SUM(H32:H35) -> 14739.822 | I36: =SUM(I32:I35) -> 10399.18 | J36: =SUM(J32:J35) -> 1

Sheet sortedby_social_group
A1: hhid | B1: Sampling sl.no. | C1: soc_grp | D1: hhsz | E1: mhuce | F1: AE_clo&fw | G1: edu_lvl
A2: 11443_2_02 | B2: 6 | C2: 1 | D2: 4 | E2: 7171 | F2: 8600 | G2: 10
A3: 23140_4_02 | B3: 10 | C3: 1 | D3: 3 | E3: 6338 | F3: 6500 | G3: 01
A4: 13169_1_01 | B4: 42 | C4: 1 | D4: 5 | E4: 19917 | F4: 10000 | G4: 12
A5: 13542_2_01 | B5: 53 | C5: 1 | D5: 3 | E5: 16805 | F5: 9660 | G5: 12
A6: 15519_2_02 | B6: 69 | C6: 1 | D6: 4 | E6: 6167 | F6: 3000 | G6: 10
A7: 11654_1_02 | B7: 73 | C7: 1 | D7: 6 | E7: 17148 | F7: 20600 | G7: 10
A8: 12333_2_02 | B8: 75 | C8: 1 | D8: 4 | E8: 10158 | F8: 9700 | G8: 12
A9: 12432_1_01 | B9: 76 | C9: 1 | D9: 5 | E9: 13875 | F9: 9000 | G9: 11
A10: 24001_3_02 | B10: 78 | C10: 1 | D10: 5 | E10: 16417 | F10: 25000 | G10: 12
A11: 14208_1_02 | B11: 79 | C11: 1 | D11: 8 | E11: 17005 | F11: 15845 | G11: 10
A12: 13323_3_01 | B12: 80 | C12: 1 | D12: 5 | E12: 9283 | F12: 6500 | G12: 07
A13: 17415_1_01 | B13: 87 | C13: 1 | D13: 4 | E13: 17055 | F13: 20000 | G13: 12
... A254: 14057_1_01 | B254: 252 | C254: 9 | D254: 6 | E254: 16242 | F254: 12600 | G254: 12

Sheet Imp_Stratification
A1: Parameter | B1: Value
A2: N (Population Size) | B2: 253
A3: n (Sample Size) | B3: 25
A4: k (Interval = N/n) | B4: 10
A5: Random Start (r_start) | B5: 9
A7: Oder of selection | B7: Selection_Index | C7: Rounded_Index | D7: hhid | E7: Sampling sl.no. | F7: soc_grp | G7: hhsz | H7: mhuce | I7: AE_clo&fw | J7: edu_lvl
A8: 1 | B8: 9 | C8: 9 | D8: 24001_3_02 | E8: 78 | F8: 1 | G8: 5 | H8: 16417 | I8: 25000 | J8: 12
A9: 2 | B9: 19 | C9: 19 | D9: 21802_2_02 | E9: 129 | F9: 1 | G9: 2 | H9: 18567 | I9: 14000 | J9: 12
A10: 3 | B10: 29 | C10: 29 | D10: 10542_1_01 | E10: 178 | F10: 1 | G10: 6 | H10: 23250 | I10: 30000 | J10: 13
A11: 4 | B11: 39 | C11: 39 | D11: 12399_1_01 | E11: 37 | F11: 2 | G11: 4 | H11: 6833 | I11: 4000 | J11: 08
A12: 5 | B12: 49 | C12: 49 | D12: 15048_1_01 | E12: 95 | F12: 2 | G12: 5 | H12: 14521 | I12: 20300 | J12: 13
A13: 6 | B13: 59 | C13: 59 | D13: 10866_3_01 | E13: 156 | F13: 2 | G13: 2 | H13: 6583 | I13: 5000 | J13: 06
A14: 7 | B14: 69 | C14: 69 | D14: 10960_1_01 | E14: 202 | F14: 2 | G14: 2 | H14: 6317 | I14: 7100 | J14: 10
A15: 8 | B15: 79 | C15: 79 | D15: 23546_4_01 | E15: 2 | F15: 3 | G15: 1 | H15: 13889 | I15: 17800 | J15: 07
A16: 9 | B16: 89 | C16: 89 | D16: 22510_1_01 | E16: 18 | F16: 3 | G16: 14 | H16: 19985 | I16: 10740 | J16: 12
A17: 10 | B17: 99 | C17: 99 | D17: 17404_1_01 | E17: 35 | F17: 3 | G17: 3 | H17: 15502 | I17: 3500 | J17: 12
A18: 11 | B18: 109 | C18: 109 | D18: 17056_2_01 | E18: 59 | F18: 3 | G18: 5 | H18: 12467 | I18: 7000 | J18: 10
A19: 12 | B19: 119 | C19: 119 | D19: 10222_3_01 | E19: 86 | F19: 3 | G19: 1 | H19: 1457 | I19: 680 | J19: 07
... A32: 25 | B32: 249 | C32: 249 | D32: 22690_4_01 | E32: 242 | F32: 9 | G32: 2 | H32: 12608 | I32: 5200 | J32: 12
F34: N = | G34: 253
F35: n = | G35: 25
F36: Estimates under SRSWR
F37: population | G37: Avg. hh size | H37: Avg MHUCE | I37: Avg MUPCE | J37: Avg AE-Clo&fw | K37: proportion of ST households
F38: =SUM(G8:G32)*G34/G35 -> 1062.6 | G38: =SUM(G8:G32)/G35 -> 4.2 | H38: =SUM(H8:H32)/G35 -> 12869.64 | I38: =SUM(H8:H32) / SUM(G8:G32) -> 3064.2 | J38: =SUM(I8:I32)/SUM(G8:G32) -> 2715.4286 | K38: =COUNTIF(F8:F32,1)/25 -> 0.12
